[2025-07-22T10:35:14.064+0000] {taskinstance.py:1159} INFO - Dependencies all met for dep_context=non-requeueable deps ti=<TaskInstance: dashboard_loader_every_5_min.trigger_streamlit_refresh scheduled__2025-07-22T10:30:00+00:00 [queued]>
[2025-07-22T10:35:14.125+0000] {taskinstance.py:1159} INFO - Dependencies all met for dep_context=requeueable deps ti=<TaskInstance: dashboard_loader_every_5_min.trigger_streamlit_refresh scheduled__2025-07-22T10:30:00+00:00 [queued]>
[2025-07-22T10:35:14.128+0000] {taskinstance.py:1361} INFO - Starting attempt 1 of 1
[2025-07-22T10:35:14.200+0000] {taskinstance.py:1382} INFO - Executing <Task(PythonOperator): trigger_streamlit_refresh> on 2025-07-22 10:30:00+00:00
[2025-07-22T10:35:14.242+0000] {standard_task_runner.py:57} INFO - Started process 2705 to run task
[2025-07-22T10:35:14.280+0000] {standard_task_runner.py:84} INFO - Running: ['***', 'tasks', 'run', 'dashboard_loader_every_5_min', 'trigger_streamlit_refresh', 'scheduled__2025-07-22T10:30:00+00:00', '--job-id', '73', '--raw', '--subdir', 'DAGS_FOLDER/dashboard_loader_dag.py', '--cfg-path', '/tmp/tmpw4dt_qqv']
[2025-07-22T10:35:14.322+0000] {standard_task_runner.py:85} INFO - Job 73: Subtask trigger_streamlit_refresh
[2025-07-22T10:35:15.854+0000] {task_command.py:416} INFO - Running <TaskInstance: dashboard_loader_every_5_min.trigger_streamlit_refresh scheduled__2025-07-22T10:30:00+00:00 [running]> on host 539cb54e78a7
[2025-07-22T10:35:16.767+0000] {taskinstance.py:1662} INFO - Exporting env vars: AIRFLOW_CTX_DAG_OWNER='***' AIRFLOW_CTX_DAG_ID='dashboard_loader_every_5_min' AIRFLOW_CTX_TASK_ID='trigger_streamlit_refresh' AIRFLOW_CTX_EXECUTION_DATE='2025-07-22T10:30:00+00:00' AIRFLOW_CTX_TRY_NUMBER='1' AIRFLOW_CTX_DAG_RUN_ID='scheduled__2025-07-22T10:30:00+00:00'
[2025-07-22T10:35:17.652+0000] {logging_mixin.py:154} INFO - Dashboard refresh failed: HTTPConnectionPool(host='host.docker.internal', port=8501): Max retries exceeded with url: /refresh (Caused by NewConnectionError('<urllib3.connection.HTTPConnection object at 0x7d4ed0204160>: Failed to establish a new connection: [Errno 101] Network is unreachable'))
[2025-07-22T10:35:17.654+0000] {python.py:194} INFO - Done. Returned value was: None
[2025-07-22T10:35:17.736+0000] {taskinstance.py:1400} INFO - Marking task as SUCCESS. dag_id=dashboard_loader_every_5_min, task_id=trigger_streamlit_refresh, execution_date=20250722T103000, start_date=20250722T103514, end_date=20250722T103517
[2025-07-22T10:35:17.894+0000] {local_task_job_runner.py:228} INFO - Task exited with return code 0
[2025-07-22T10:35:18.023+0000] {taskinstance.py:2778} INFO - 0 downstream tasks scheduled from follow-on schedule check
