[2025-07-22T08:35:18.776+0000] {taskinstance.py:1159} INFO - Dependencies all met for dep_context=non-requeueable deps ti=<TaskInstance: dashboard_loader_every_5_min.trigger_streamlit_refresh scheduled__2025-07-22T08:30:00+00:00 [queued]>
[2025-07-22T08:35:18.797+0000] {taskinstance.py:1159} INFO - Dependencies all met for dep_context=requeueable deps ti=<TaskInstance: dashboard_loader_every_5_min.trigger_streamlit_refresh scheduled__2025-07-22T08:30:00+00:00 [queued]>
[2025-07-22T08:35:18.799+0000] {taskinstance.py:1361} INFO - Starting attempt 1 of 1
[2025-07-22T08:35:18.831+0000] {taskinstance.py:1382} INFO - Executing <Task(PythonOperator): trigger_streamlit_refresh> on 2025-07-22 08:30:00+00:00
[2025-07-22T08:35:18.849+0000] {standard_task_runner.py:57} INFO - Started process 1023 to run task
[2025-07-22T08:35:18.859+0000] {standard_task_runner.py:84} INFO - Running: ['***', 'tasks', 'run', 'dashboard_loader_every_5_min', 'trigger_streamlit_refresh', 'scheduled__2025-07-22T08:30:00+00:00', '--job-id', '21', '--raw', '--subdir', 'DAGS_FOLDER/dashboard_loader_dag.py', '--cfg-path', '/tmp/tmpnq_4j503']
[2025-07-22T08:35:18.869+0000] {standard_task_runner.py:85} INFO - Job 21: Subtask trigger_streamlit_refresh
[2025-07-22T08:35:19.138+0000] {task_command.py:416} INFO - Running <TaskInstance: dashboard_loader_every_5_min.trigger_streamlit_refresh scheduled__2025-07-22T08:30:00+00:00 [running]> on host 539cb54e78a7
[2025-07-22T08:35:19.439+0000] {taskinstance.py:1662} INFO - Exporting env vars: AIRFLOW_CTX_DAG_OWNER='***' AIRFLOW_CTX_DAG_ID='dashboard_loader_every_5_min' AIRFLOW_CTX_TASK_ID='trigger_streamlit_refresh' AIRFLOW_CTX_EXECUTION_DATE='2025-07-22T08:30:00+00:00' AIRFLOW_CTX_TRY_NUMBER='1' AIRFLOW_CTX_DAG_RUN_ID='scheduled__2025-07-22T08:30:00+00:00'
[2025-07-22T08:35:19.647+0000] {logging_mixin.py:154} INFO - Dashboard refresh failed: HTTPConnectionPool(host='host.docker.internal', port=8501): Max retries exceeded with url: /refresh (Caused by NewConnectionError('<urllib3.connection.HTTPConnection object at 0x7d4ed01c7ac0>: Failed to establish a new connection: [Errno 101] Network is unreachable'))
[2025-07-22T08:35:19.649+0000] {python.py:194} INFO - Done. Returned value was: None
[2025-07-22T08:35:19.671+0000] {taskinstance.py:1400} INFO - Marking task as SUCCESS. dag_id=dashboard_loader_every_5_min, task_id=trigger_streamlit_refresh, execution_date=20250722T083000, start_date=20250722T083518, end_date=20250722T083519
[2025-07-22T08:35:19.723+0000] {local_task_job_runner.py:228} INFO - Task exited with return code 0
[2025-07-22T08:35:19.772+0000] {taskinstance.py:2778} INFO - 0 downstream tasks scheduled from follow-on schedule check
