[2025-07-22T18:37:20.514+0000] {taskinstance.py:1159} INFO - Dependencies all met for dep_context=non-requeueable deps ti=<TaskInstance: simulate_data_every_5_seconds.hit_flask_api_12_times scheduled__2025-07-22T18:36:00+00:00 [queued]>
[2025-07-22T18:37:20.542+0000] {taskinstance.py:1159} INFO - Dependencies all met for dep_context=requeueable deps ti=<TaskInstance: simulate_data_every_5_seconds.hit_flask_api_12_times scheduled__2025-07-22T18:36:00+00:00 [queued]>
[2025-07-22T18:37:20.543+0000] {taskinstance.py:1361} INFO - Starting attempt 1 of 1
[2025-07-22T18:37:20.570+0000] {taskinstance.py:1382} INFO - Executing <Task(PythonOperator): hit_flask_api_12_times> on 2025-07-22 18:36:00+00:00
[2025-07-22T18:37:20.703+0000] {standard_task_runner.py:57} INFO - Started process 3146 to run task
[2025-07-22T18:37:20.713+0000] {standard_task_runner.py:84} INFO - Running: ['***', 'tasks', 'run', 'simulate_data_every_5_seconds', 'hit_flask_api_12_times', 'scheduled__2025-07-22T18:36:00+00:00', '--job-id', '118', '--raw', '--subdir', 'DAGS_FOLDER/simulate_data_dag.py', '--cfg-path', '/tmp/tmpldhsgtwj']
[2025-07-22T18:37:20.719+0000] {standard_task_runner.py:85} INFO - Job 118: Subtask hit_flask_api_12_times
[2025-07-22T18:37:21.304+0000] {task_command.py:416} INFO - Running <TaskInstance: simulate_data_every_5_seconds.hit_flask_api_12_times scheduled__2025-07-22T18:36:00+00:00 [running]> on host 539cb54e78a7
[2025-07-22T18:37:21.625+0000] {taskinstance.py:1662} INFO - Exporting env vars: AIRFLOW_CTX_DAG_OWNER='***' AIRFLOW_CTX_DAG_ID='simulate_data_every_5_seconds' AIRFLOW_CTX_TASK_ID='hit_flask_api_12_times' AIRFLOW_CTX_EXECUTION_DATE='2025-07-22T18:36:00+00:00' AIRFLOW_CTX_TRY_NUMBER='1' AIRFLOW_CTX_DAG_RUN_ID='scheduled__2025-07-22T18:36:00+00:00'
[2025-07-22T18:37:24.947+0000] {logging_mixin.py:154} INFO - Failed to connect to http://host.docker.internal:5000: HTTPConnectionPool(host='host.docker.internal', port=5000): Read timed out. (read timeout=3)
[2025-07-22T18:37:24.966+0000] {logging_mixin.py:154} INFO - Failed to connect to http://172.17.0.1:5000: HTTPConnectionPool(host='172.17.0.1', port=5000): Max retries exceeded with url: /send-vitals (Caused by NewConnectionError('<urllib3.connection.HTTPConnection object at 0x7d4ed0192040>: Failed to establish a new connection: [Errno 111] Connection refused'))
[2025-07-22T18:37:28.084+0000] {logging_mixin.py:154} INFO - Failed to connect to http://gateway.docker.internal:5000: HTTPConnectionPool(host='gateway.docker.internal', port=5000): Max retries exceeded with url: /send-vitals (Caused by NewConnectionError('<urllib3.connection.HTTPConnection object at 0x7d4ed0149d60>: Failed to establish a new connection: [Errno 101] Network is unreachable'))
[2025-07-22T18:37:28.092+0000] {logging_mixin.py:154} INFO - Could not connect to Flask app with any URL
[2025-07-22T18:37:28.096+0000] {python.py:194} INFO - Done. Returned value was: None
[2025-07-22T18:37:28.127+0000] {taskinstance.py:1400} INFO - Marking task as SUCCESS. dag_id=simulate_data_every_5_seconds, task_id=hit_flask_api_12_times, execution_date=20250722T183600, start_date=20250722T183720, end_date=20250722T183728
[2025-07-22T18:37:28.193+0000] {local_task_job_runner.py:228} INFO - Task exited with return code 0
[2025-07-22T18:37:28.310+0000] {taskinstance.py:2778} INFO - 0 downstream tasks scheduled from follow-on schedule check
