[2025-07-22T18:50:28.069+0000] {taskinstance.py:1159} INFO - Dependencies all met for dep_context=non-requeueable deps ti=<TaskInstance: dashboard_loader_every_5_min.trigger_streamlit_refresh scheduled__2025-07-22T18:45:00+00:00 [queued]>
[2025-07-22T18:50:28.143+0000] {taskinstance.py:1159} INFO - Dependencies all met for dep_context=requeueable deps ti=<TaskInstance: dashboard_loader_every_5_min.trigger_streamlit_refresh scheduled__2025-07-22T18:45:00+00:00 [queued]>
[2025-07-22T18:50:28.150+0000] {taskinstance.py:1361} INFO - Starting attempt 1 of 1
[2025-07-22T18:50:28.340+0000] {taskinstance.py:1382} INFO - Executing <Task(PythonOperator): trigger_streamlit_refresh> on 2025-07-22 18:45:00+00:00
[2025-07-22T18:50:28.562+0000] {standard_task_runner.py:57} INFO - Started process 3364 to run task
[2025-07-22T18:50:28.610+0000] {standard_task_runner.py:84} INFO - Running: ['***', 'tasks', 'run', 'dashboard_loader_every_5_min', 'trigger_streamlit_refresh', 'scheduled__2025-07-22T18:45:00+00:00', '--job-id', '135', '--raw', '--subdir', 'DAGS_FOLDER/dashboard_loader_dag.py', '--cfg-path', '/tmp/tmpvgs_huuv']
[2025-07-22T18:50:28.666+0000] {standard_task_runner.py:85} INFO - Job 135: Subtask trigger_streamlit_refresh
[2025-07-22T18:50:30.080+0000] {task_command.py:416} INFO - Running <TaskInstance: dashboard_loader_every_5_min.trigger_streamlit_refresh scheduled__2025-07-22T18:45:00+00:00 [running]> on host 539cb54e78a7
[2025-07-22T18:50:31.133+0000] {taskinstance.py:1662} INFO - Exporting env vars: AIRFLOW_CTX_DAG_OWNER='***' AIRFLOW_CTX_DAG_ID='dashboard_loader_every_5_min' AIRFLOW_CTX_TASK_ID='trigger_streamlit_refresh' AIRFLOW_CTX_EXECUTION_DATE='2025-07-22T18:45:00+00:00' AIRFLOW_CTX_TRY_NUMBER='1' AIRFLOW_CTX_DAG_RUN_ID='scheduled__2025-07-22T18:45:00+00:00'
[2025-07-22T18:50:31.466+0000] {logging_mixin.py:154} INFO - Dashboard refresh failed: HTTPConnectionPool(host='host.docker.internal', port=8501): Max retries exceeded with url: /refresh (Caused by NewConnectionError('<urllib3.connection.HTTPConnection object at 0x7d4ed0227100>: Failed to establish a new connection: [Errno 101] Network is unreachable'))
[2025-07-22T18:50:31.469+0000] {python.py:194} INFO - Done. Returned value was: None
[2025-07-22T18:50:31.597+0000] {taskinstance.py:1400} INFO - Marking task as SUCCESS. dag_id=dashboard_loader_every_5_min, task_id=trigger_streamlit_refresh, execution_date=20250722T184500, start_date=20250722T185028, end_date=20250722T185031
[2025-07-22T18:50:32.071+0000] {local_task_job_runner.py:228} INFO - Task exited with return code 0
[2025-07-22T18:50:32.480+0000] {taskinstance.py:2778} INFO - 0 downstream tasks scheduled from follow-on schedule check
