[2025-07-22T22:28:08.657+0000] {taskinstance.py:1159} INFO - Dependencies all met for dep_context=non-requeueable deps ti=<TaskInstance: dashboard_loader_every_5_min.trigger_streamlit_refresh scheduled__2025-07-22T19:25:00+00:00 [queued]>
[2025-07-22T22:28:08.767+0000] {taskinstance.py:1159} INFO - Dependencies all met for dep_context=requeueable deps ti=<TaskInstance: dashboard_loader_every_5_min.trigger_streamlit_refresh scheduled__2025-07-22T19:25:00+00:00 [queued]>
[2025-07-22T22:28:08.770+0000] {taskinstance.py:1361} INFO - Starting attempt 1 of 1
[2025-07-22T22:28:08.868+0000] {taskinstance.py:1382} INFO - Executing <Task(PythonOperator): trigger_streamlit_refresh> on 2025-07-22 19:25:00+00:00
[2025-07-22T22:28:08.932+0000] {standard_task_runner.py:57} INFO - Started process 4026 to run task
[2025-07-22T22:28:09.002+0000] {standard_task_runner.py:84} INFO - Running: ['***', 'tasks', 'run', 'dashboard_loader_every_5_min', 'trigger_streamlit_refresh', 'scheduled__2025-07-22T19:25:00+00:00', '--job-id', '191', '--raw', '--subdir', 'DAGS_FOLDER/dashboard_loader_dag.py', '--cfg-path', '/tmp/tmpykyri1k_']
[2025-07-22T22:28:09.040+0000] {standard_task_runner.py:85} INFO - Job 191: Subtask trigger_streamlit_refresh
[2025-07-22T22:28:10.150+0000] {task_command.py:416} INFO - Running <TaskInstance: dashboard_loader_every_5_min.trigger_streamlit_refresh scheduled__2025-07-22T19:25:00+00:00 [running]> on host 539cb54e78a7
[2025-07-22T22:28:11.060+0000] {taskinstance.py:1662} INFO - Exporting env vars: AIRFLOW_CTX_DAG_OWNER='***' AIRFLOW_CTX_DAG_ID='dashboard_loader_every_5_min' AIRFLOW_CTX_TASK_ID='trigger_streamlit_refresh' AIRFLOW_CTX_EXECUTION_DATE='2025-07-22T19:25:00+00:00' AIRFLOW_CTX_TRY_NUMBER='1' AIRFLOW_CTX_DAG_RUN_ID='scheduled__2025-07-22T19:25:00+00:00'
[2025-07-22T22:28:21.388+0000] {logging_mixin.py:154} INFO - Dashboard refresh failed: HTTPConnectionPool(host='host.docker.internal', port=8501): Max retries exceeded with url: /refresh (Caused by NewConnectionError('<urllib3.connection.HTTPConnection object at 0x7d4ed01c8ac0>: Failed to establish a new connection: [Errno -3] Temporary failure in name resolution'))
[2025-07-22T22:28:21.746+0000] {python.py:194} INFO - Done. Returned value was: None
[2025-07-22T22:28:24.703+0000] {job.py:219} ERROR - Job heartbeat got an exception
Traceback (most recent call last):
  File "/home/airflow/.local/lib/python3.8/site-packages/sqlalchemy/engine/base.py", line 3371, in _wrap_pool_connect
    return fn()
  File "/home/airflow/.local/lib/python3.8/site-packages/sqlalchemy/pool/base.py", line 327, in connect
    return _ConnectionFairy._checkout(self)
  File "/home/airflow/.local/lib/python3.8/site-packages/sqlalchemy/pool/base.py", line 894, in _checkout
    fairy = _ConnectionRecord.checkout(pool)
  File "/home/airflow/.local/lib/python3.8/site-packages/sqlalchemy/pool/base.py", line 493, in checkout
    rec = pool._do_get()
  File "/home/airflow/.local/lib/python3.8/site-packages/sqlalchemy/pool/impl.py", line 256, in _do_get
    return self._create_connection()
  File "/home/airflow/.local/lib/python3.8/site-packages/sqlalchemy/pool/base.py", line 273, in _create_connection
    return _ConnectionRecord(self)
  File "/home/airflow/.local/lib/python3.8/site-packages/sqlalchemy/pool/base.py", line 388, in __init__
    self.__connect()
  File "/home/airflow/.local/lib/python3.8/site-packages/sqlalchemy/pool/base.py", line 691, in __connect
    pool.logger.debug("Error on connect(): %s", e)
  File "/home/airflow/.local/lib/python3.8/site-packages/sqlalchemy/util/langhelpers.py", line 70, in __exit__
    compat.raise_(
  File "/home/airflow/.local/lib/python3.8/site-packages/sqlalchemy/util/compat.py", line 211, in raise_
    raise exception
  File "/home/airflow/.local/lib/python3.8/site-packages/sqlalchemy/pool/base.py", line 686, in __connect
    self.dbapi_connection = connection = pool._invoke_creator(self)
  File "/home/airflow/.local/lib/python3.8/site-packages/sqlalchemy/engine/create.py", line 574, in connect
    return dialect.connect(*cargs, **cparams)
  File "/home/airflow/.local/lib/python3.8/site-packages/sqlalchemy/engine/default.py", line 598, in connect
    return self.dbapi.connect(*cargs, **cparams)
  File "/home/airflow/.local/lib/python3.8/site-packages/psycopg2/__init__.py", line 122, in connect
    conn = _connect(dsn, connection_factory=connection_factory, **kwasync)
psycopg2.OperationalError: could not translate host name "postgres" to address: Temporary failure in name resolution


The above exception was the direct cause of the following exception:

Traceback (most recent call last):
  File "/home/airflow/.local/lib/python3.8/site-packages/airflow/jobs/job.py", line 190, in heartbeat
    session.merge(self)
  File "/home/airflow/.local/lib/python3.8/site-packages/sqlalchemy/orm/session.py", line 3056, in merge
    return self._merge(
  File "/home/airflow/.local/lib/python3.8/site-packages/sqlalchemy/orm/session.py", line 3136, in _merge
    merged = self.get(
  File "/home/airflow/.local/lib/python3.8/site-packages/sqlalchemy/orm/session.py", line 2853, in get
    return self._get_impl(
  File "/home/airflow/.local/lib/python3.8/site-packages/sqlalchemy/orm/session.py", line 2975, in _get_impl
    return db_load_fn(
  File "/home/airflow/.local/lib/python3.8/site-packages/sqlalchemy/orm/loading.py", line 530, in load_on_pk_identity
    session.execute(
  File "/home/airflow/.local/lib/python3.8/site-packages/sqlalchemy/orm/session.py", line 1716, in execute
    conn = self._connection_for_bind(bind)
  File "/home/airflow/.local/lib/python3.8/site-packages/sqlalchemy/orm/session.py", line 1555, in _connection_for_bind
    return self._transaction._connection_for_bind(
  File "/home/airflow/.local/lib/python3.8/site-packages/sqlalchemy/orm/session.py", line 750, in _connection_for_bind
    conn = bind.connect()
  File "/home/airflow/.local/lib/python3.8/site-packages/sqlalchemy/future/engine.py", line 406, in connect
    return super(Engine, self).connect()
  File "/home/airflow/.local/lib/python3.8/site-packages/sqlalchemy/engine/base.py", line 3325, in connect
    return self._connection_cls(self, close_with_result=close_with_result)
  File "/home/airflow/.local/lib/python3.8/site-packages/sqlalchemy/engine/base.py", line 96, in __init__
    else engine.raw_connection()
  File "/home/airflow/.local/lib/python3.8/site-packages/sqlalchemy/engine/base.py", line 3404, in raw_connection
    return self._wrap_pool_connect(self.pool.connect, _connection)
  File "/home/airflow/.local/lib/python3.8/site-packages/sqlalchemy/engine/base.py", line 3374, in _wrap_pool_connect
    Connection._handle_dbapi_exception_noconnection(
  File "/home/airflow/.local/lib/python3.8/site-packages/sqlalchemy/engine/base.py", line 2208, in _handle_dbapi_exception_noconnection
    util.raise_(
  File "/home/airflow/.local/lib/python3.8/site-packages/sqlalchemy/util/compat.py", line 211, in raise_
    raise exception
  File "/home/airflow/.local/lib/python3.8/site-packages/sqlalchemy/engine/base.py", line 3371, in _wrap_pool_connect
    return fn()
  File "/home/airflow/.local/lib/python3.8/site-packages/sqlalchemy/pool/base.py", line 327, in connect
    return _ConnectionFairy._checkout(self)
  File "/home/airflow/.local/lib/python3.8/site-packages/sqlalchemy/pool/base.py", line 894, in _checkout
    fairy = _ConnectionRecord.checkout(pool)
  File "/home/airflow/.local/lib/python3.8/site-packages/sqlalchemy/pool/base.py", line 493, in checkout
    rec = pool._do_get()
  File "/home/airflow/.local/lib/python3.8/site-packages/sqlalchemy/pool/impl.py", line 256, in _do_get
    return self._create_connection()
  File "/home/airflow/.local/lib/python3.8/site-packages/sqlalchemy/pool/base.py", line 273, in _create_connection
    return _ConnectionRecord(self)
  File "/home/airflow/.local/lib/python3.8/site-packages/sqlalchemy/pool/base.py", line 388, in __init__
    self.__connect()
  File "/home/airflow/.local/lib/python3.8/site-packages/sqlalchemy/pool/base.py", line 691, in __connect
    pool.logger.debug("Error on connect(): %s", e)
  File "/home/airflow/.local/lib/python3.8/site-packages/sqlalchemy/util/langhelpers.py", line 70, in __exit__
    compat.raise_(
  File "/home/airflow/.local/lib/python3.8/site-packages/sqlalchemy/util/compat.py", line 211, in raise_
    raise exception
  File "/home/airflow/.local/lib/python3.8/site-packages/sqlalchemy/pool/base.py", line 686, in __connect
    self.dbapi_connection = connection = pool._invoke_creator(self)
  File "/home/airflow/.local/lib/python3.8/site-packages/sqlalchemy/engine/create.py", line 574, in connect
    return dialect.connect(*cargs, **cparams)
  File "/home/airflow/.local/lib/python3.8/site-packages/sqlalchemy/engine/default.py", line 598, in connect
    return self.dbapi.connect(*cargs, **cparams)
  File "/home/airflow/.local/lib/python3.8/site-packages/psycopg2/__init__.py", line 122, in connect
    conn = _connect(dsn, connection_factory=connection_factory, **kwasync)
sqlalchemy.exc.OperationalError: (psycopg2.OperationalError) could not translate host name "postgres" to address: Temporary failure in name resolution

(Background on this error at: https://sqlalche.me/e/14/e3q8)
[2025-07-23T01:31:39.453+0000] {local_task_job_runner.py:205} ERROR - Heartbeat time limit exceeded!
[2025-07-23T04:31:53.872+0000] {process_utils.py:131} INFO - Sending 15 to group 4026. PIDs of all processes in the group: [4026]
[2025-07-23T04:31:57.528+0000] {process_utils.py:86} INFO - Sending the signal 15 to group 4026
[2025-07-23T04:31:59.028+0000] {taskinstance.py:1632} ERROR - Received SIGTERM. Terminating subprocesses.
[2025-07-23T04:31:59.471+0000] {logging_mixin.py:154} WARNING - --- Logging error ---
[2025-07-23T04:32:02.509+0000] {logging_mixin.py:154} WARNING - Traceback (most recent call last):
[2025-07-23T04:32:02.530+0000] {logging_mixin.py:154} WARNING -   File "/home/***/.local/lib/python3.8/site-packages/sqlalchemy/engine/base.py", line 3371, in _wrap_pool_connect
    return fn()
[2025-07-23T04:32:02.568+0000] {logging_mixin.py:154} WARNING -   File "/home/***/.local/lib/python3.8/site-packages/sqlalchemy/pool/base.py", line 327, in connect
    return _ConnectionFairy._checkout(self)
[2025-07-23T04:32:02.600+0000] {logging_mixin.py:154} WARNING -   File "/home/***/.local/lib/python3.8/site-packages/sqlalchemy/pool/base.py", line 894, in _checkout
    fairy = _ConnectionRecord.checkout(pool)
[2025-07-23T04:32:02.624+0000] {logging_mixin.py:154} WARNING -   File "/home/***/.local/lib/python3.8/site-packages/sqlalchemy/pool/base.py", line 493, in checkout
    rec = pool._do_get()
[2025-07-23T04:32:02.684+0000] {logging_mixin.py:154} WARNING -   File "/home/***/.local/lib/python3.8/site-packages/sqlalchemy/pool/impl.py", line 256, in _do_get
    return self._create_connection()
[2025-07-23T04:32:02.700+0000] {logging_mixin.py:154} WARNING -   File "/home/***/.local/lib/python3.8/site-packages/sqlalchemy/pool/base.py", line 273, in _create_connection
    return _ConnectionRecord(self)
[2025-07-23T04:32:02.707+0000] {logging_mixin.py:154} WARNING -   File "/home/***/.local/lib/python3.8/site-packages/sqlalchemy/pool/base.py", line 388, in __init__
    self.__connect()
[2025-07-23T04:32:02.710+0000] {logging_mixin.py:154} WARNING -   File "/home/***/.local/lib/python3.8/site-packages/sqlalchemy/pool/base.py", line 691, in __connect
    pool.logger.debug("Error on connect(): %s", e)
[2025-07-23T04:32:02.716+0000] {logging_mixin.py:154} WARNING -   File "/home/***/.local/lib/python3.8/site-packages/sqlalchemy/util/langhelpers.py", line 70, in __exit__
    compat.raise_(
[2025-07-23T04:32:02.725+0000] {logging_mixin.py:154} WARNING -   File "/home/***/.local/lib/python3.8/site-packages/sqlalchemy/util/compat.py", line 211, in raise_
    raise exception
[2025-07-23T04:32:02.730+0000] {logging_mixin.py:154} WARNING -   File "/home/***/.local/lib/python3.8/site-packages/sqlalchemy/pool/base.py", line 686, in __connect
    self.dbapi_connection = connection = pool._invoke_creator(self)
[2025-07-23T04:32:02.786+0000] {logging_mixin.py:154} WARNING -   File "/home/***/.local/lib/python3.8/site-packages/sqlalchemy/engine/create.py", line 574, in connect
    return dialect.connect(*cargs, **cparams)
[2025-07-23T04:32:02.818+0000] {logging_mixin.py:154} WARNING -   File "/home/***/.local/lib/python3.8/site-packages/sqlalchemy/engine/default.py", line 598, in connect
    return self.dbapi.connect(*cargs, **cparams)
[2025-07-23T04:32:02.823+0000] {logging_mixin.py:154} WARNING -   File "/home/***/.local/lib/python3.8/site-packages/psycopg2/__init__.py", line 122, in connect
    conn = _connect(dsn, connection_factory=connection_factory, **kwasync)
[2025-07-23T04:32:02.834+0000] {logging_mixin.py:154} WARNING - psycopg2.OperationalError: could not translate host name "postgres" to address: Temporary failure in name resolution
[2025-07-23T04:32:02.995+0000] {logging_mixin.py:154} WARNING - 
The above exception was the direct cause of the following exception:
[2025-07-23T04:32:03.033+0000] {logging_mixin.py:154} WARNING - Traceback (most recent call last):
[2025-07-23T04:32:03.036+0000] {logging_mixin.py:154} WARNING -   File "/home/***/.local/lib/python3.8/site-packages/***/models/taskinstance.py", line 1520, in _run_raw_task
    self.refresh_from_db(lock_for_update=True, session=session)
[2025-07-23T04:32:03.049+0000] {logging_mixin.py:154} WARNING -   File "/home/***/.local/lib/python3.8/site-packages/***/utils/session.py", line 76, in wrapper
    return func(*args, **kwargs)
[2025-07-23T04:32:03.081+0000] {logging_mixin.py:154} WARNING -   File "/home/***/.local/lib/python3.8/site-packages/***/models/taskinstance.py", line 862, in refresh_from_db
    for attempt in run_with_db_retries(logger=self.log):
[2025-07-23T04:32:03.088+0000] {logging_mixin.py:154} WARNING -   File "/home/***/.local/lib/python3.8/site-packages/tenacity/__init__.py", line 347, in __iter__
    do = self.iter(retry_state=retry_state)
[2025-07-23T04:32:03.098+0000] {logging_mixin.py:154} WARNING -   File "/home/***/.local/lib/python3.8/site-packages/tenacity/__init__.py", line 325, in iter
    raise retry_exc.reraise()
[2025-07-23T04:32:03.197+0000] {logging_mixin.py:154} WARNING -   File "/home/***/.local/lib/python3.8/site-packages/tenacity/__init__.py", line 158, in reraise
    raise self.last_attempt.result()
[2025-07-23T04:32:03.200+0000] {logging_mixin.py:154} WARNING -   File "/usr/local/lib/python3.8/concurrent/futures/_base.py", line 437, in result
    return self.__get_result()
[2025-07-23T04:32:03.204+0000] {logging_mixin.py:154} WARNING -   File "/usr/local/lib/python3.8/concurrent/futures/_base.py", line 389, in __get_result
    raise self._exception
[2025-07-23T04:32:03.231+0000] {logging_mixin.py:154} WARNING -   File "/home/***/.local/lib/python3.8/site-packages/***/models/taskinstance.py", line 864, in refresh_from_db
    ti: TaskInstance | None = qry.with_for_update().one_or_none()
[2025-07-23T04:32:03.237+0000] {logging_mixin.py:154} WARNING -   File "/home/***/.local/lib/python3.8/site-packages/sqlalchemy/orm/query.py", line 2850, in one_or_none
    return self._iter().one_or_none()
[2025-07-23T04:32:03.240+0000] {logging_mixin.py:154} WARNING -   File "/home/***/.local/lib/python3.8/site-packages/sqlalchemy/orm/query.py", line 2916, in _iter
    result = self.session.execute(
[2025-07-23T04:32:03.242+0000] {logging_mixin.py:154} WARNING -   File "/home/***/.local/lib/python3.8/site-packages/sqlalchemy/orm/session.py", line 1716, in execute
    conn = self._connection_for_bind(bind)
[2025-07-23T04:32:03.247+0000] {logging_mixin.py:154} WARNING -   File "/home/***/.local/lib/python3.8/site-packages/sqlalchemy/orm/session.py", line 1555, in _connection_for_bind
    return self._transaction._connection_for_bind(
[2025-07-23T04:32:03.257+0000] {logging_mixin.py:154} WARNING -   File "/home/***/.local/lib/python3.8/site-packages/sqlalchemy/orm/session.py", line 750, in _connection_for_bind
    conn = bind.connect()
[2025-07-23T04:32:03.262+0000] {logging_mixin.py:154} WARNING -   File "/home/***/.local/lib/python3.8/site-packages/sqlalchemy/future/engine.py", line 406, in connect
    return super(Engine, self).connect()
[2025-07-23T04:32:03.266+0000] {logging_mixin.py:154} WARNING -   File "/home/***/.local/lib/python3.8/site-packages/sqlalchemy/engine/base.py", line 3325, in connect
    return self._connection_cls(self, close_with_result=close_with_result)
[2025-07-23T04:32:03.267+0000] {logging_mixin.py:154} WARNING -   File "/home/***/.local/lib/python3.8/site-packages/sqlalchemy/engine/base.py", line 96, in __init__
    else engine.raw_connection()
[2025-07-23T04:32:03.269+0000] {logging_mixin.py:154} WARNING -   File "/home/***/.local/lib/python3.8/site-packages/sqlalchemy/engine/base.py", line 3404, in raw_connection
    return self._wrap_pool_connect(self.pool.connect, _connection)
[2025-07-23T04:32:03.272+0000] {logging_mixin.py:154} WARNING -   File "/home/***/.local/lib/python3.8/site-packages/sqlalchemy/engine/base.py", line 3374, in _wrap_pool_connect
    Connection._handle_dbapi_exception_noconnection(
[2025-07-23T04:32:03.274+0000] {logging_mixin.py:154} WARNING -   File "/home/***/.local/lib/python3.8/site-packages/sqlalchemy/engine/base.py", line 2208, in _handle_dbapi_exception_noconnection
    util.raise_(
[2025-07-23T04:32:03.275+0000] {logging_mixin.py:154} WARNING -   File "/home/***/.local/lib/python3.8/site-packages/sqlalchemy/util/compat.py", line 211, in raise_
    raise exception
[2025-07-23T04:32:03.285+0000] {logging_mixin.py:154} WARNING -   File "/home/***/.local/lib/python3.8/site-packages/sqlalchemy/engine/base.py", line 3371, in _wrap_pool_connect
    return fn()
[2025-07-23T04:32:03.289+0000] {logging_mixin.py:154} WARNING -   File "/home/***/.local/lib/python3.8/site-packages/sqlalchemy/pool/base.py", line 327, in connect
    return _ConnectionFairy._checkout(self)
[2025-07-23T04:32:03.297+0000] {logging_mixin.py:154} WARNING -   File "/home/***/.local/lib/python3.8/site-packages/sqlalchemy/pool/base.py", line 894, in _checkout
    fairy = _ConnectionRecord.checkout(pool)
[2025-07-23T04:32:03.318+0000] {logging_mixin.py:154} WARNING -   File "/home/***/.local/lib/python3.8/site-packages/sqlalchemy/pool/base.py", line 493, in checkout
    rec = pool._do_get()
[2025-07-23T04:32:03.337+0000] {logging_mixin.py:154} WARNING -   File "/home/***/.local/lib/python3.8/site-packages/sqlalchemy/pool/impl.py", line 256, in _do_get
    return self._create_connection()
[2025-07-23T04:32:03.355+0000] {logging_mixin.py:154} WARNING -   File "/home/***/.local/lib/python3.8/site-packages/sqlalchemy/pool/base.py", line 273, in _create_connection
    return _ConnectionRecord(self)
[2025-07-23T04:32:03.374+0000] {logging_mixin.py:154} WARNING -   File "/home/***/.local/lib/python3.8/site-packages/sqlalchemy/pool/base.py", line 388, in __init__
    self.__connect()
[2025-07-23T04:32:03.378+0000] {logging_mixin.py:154} WARNING -   File "/home/***/.local/lib/python3.8/site-packages/sqlalchemy/pool/base.py", line 691, in __connect
    pool.logger.debug("Error on connect(): %s", e)
[2025-07-23T04:32:03.393+0000] {logging_mixin.py:154} WARNING -   File "/home/***/.local/lib/python3.8/site-packages/sqlalchemy/util/langhelpers.py", line 70, in __exit__
    compat.raise_(
[2025-07-23T04:32:03.397+0000] {logging_mixin.py:154} WARNING -   File "/home/***/.local/lib/python3.8/site-packages/sqlalchemy/util/compat.py", line 211, in raise_
    raise exception
[2025-07-23T04:32:03.465+0000] {logging_mixin.py:154} WARNING -   File "/home/***/.local/lib/python3.8/site-packages/sqlalchemy/pool/base.py", line 686, in __connect
    self.dbapi_connection = connection = pool._invoke_creator(self)
[2025-07-23T04:32:03.484+0000] {logging_mixin.py:154} WARNING -   File "/home/***/.local/lib/python3.8/site-packages/sqlalchemy/engine/create.py", line 574, in connect
    return dialect.connect(*cargs, **cparams)
[2025-07-23T04:32:03.502+0000] {logging_mixin.py:154} WARNING -   File "/home/***/.local/lib/python3.8/site-packages/sqlalchemy/engine/default.py", line 598, in connect
    return self.dbapi.connect(*cargs, **cparams)
[2025-07-23T04:32:03.510+0000] {logging_mixin.py:154} WARNING -   File "/home/***/.local/lib/python3.8/site-packages/psycopg2/__init__.py", line 122, in connect
    conn = _connect(dsn, connection_factory=connection_factory, **kwasync)
[2025-07-23T04:32:03.526+0000] {logging_mixin.py:154} WARNING - sqlalchemy.exc.OperationalError: (psycopg2.OperationalError) could not translate host name "postgres" to address: Temporary failure in name resolution

(Background on this error at: https://sqlalche.me/e/14/e3q8)
[2025-07-23T04:32:03.533+0000] {logging_mixin.py:154} WARNING - 
During handling of the above exception, another exception occurred:
[2025-07-23T04:32:03.543+0000] {logging_mixin.py:154} WARNING - Traceback (most recent call last):
[2025-07-23T04:32:03.549+0000] {logging_mixin.py:154} WARNING -   File "/usr/local/lib/python3.8/logging/__init__.py", line 1085, in emit
    msg = self.format(record)
[2025-07-23T04:32:03.556+0000] {logging_mixin.py:154} WARNING -   File "/usr/local/lib/python3.8/logging/__init__.py", line 929, in format
    return fmt.format(record)
[2025-07-23T04:32:03.594+0000] {logging_mixin.py:154} WARNING -   File "/usr/local/lib/python3.8/logging/__init__.py", line 676, in format
    record.exc_text = self.formatException(record.exc_info)
[2025-07-23T04:32:03.620+0000] {logging_mixin.py:154} WARNING -   File "/usr/local/lib/python3.8/logging/__init__.py", line 626, in formatException
    traceback.print_exception(ei[0], ei[1], tb, None, sio)
[2025-07-23T04:32:03.627+0000] {logging_mixin.py:154} WARNING -   File "/usr/local/lib/python3.8/traceback.py", line 103, in print_exception
    for line in TracebackException(
[2025-07-23T04:32:03.633+0000] {logging_mixin.py:154} WARNING -   File "/home/***/.local/lib/python3.8/site-packages/exceptiongroup/_formatting.py", line 96, in __init__
    self.stack = traceback.StackSummary.extract(
[2025-07-23T04:32:03.647+0000] {logging_mixin.py:154} WARNING -   File "/usr/local/lib/python3.8/traceback.py", line 366, in extract
    f.line
[2025-07-23T04:32:03.652+0000] {logging_mixin.py:154} WARNING -   File "/usr/local/lib/python3.8/traceback.py", line 288, in line
    self._line = linecache.getline(self.filename, self.lineno).strip()
[2025-07-23T04:32:03.668+0000] {logging_mixin.py:154} WARNING -   File "/usr/local/lib/python3.8/linecache.py", line 16, in getline
    lines = getlines(filename, module_globals)
[2025-07-23T04:32:03.670+0000] {logging_mixin.py:154} WARNING -   File "/usr/local/lib/python3.8/linecache.py", line 47, in getlines
    return updatecache(filename, module_globals)
[2025-07-23T04:32:03.671+0000] {logging_mixin.py:154} WARNING -   File "/usr/local/lib/python3.8/linecache.py", line 136, in updatecache
    with tokenize.open(fullname) as fp:
[2025-07-23T04:32:03.673+0000] {logging_mixin.py:154} WARNING -   File "/usr/local/lib/python3.8/tokenize.py", line 394, in open
    encoding, lines = detect_encoding(buffer.readline)
[2025-07-23T04:32:03.677+0000] {logging_mixin.py:154} WARNING -   File "/usr/local/lib/python3.8/tokenize.py", line 312, in detect_encoding
    try:
[2025-07-23T04:32:03.689+0000] {logging_mixin.py:154} WARNING -   File "/home/***/.local/lib/python3.8/site-packages/***/models/taskinstance.py", line 1634, in signal_handler
    raise AirflowException("Task received SIGTERM signal")
[2025-07-23T04:32:03.724+0000] {logging_mixin.py:154} WARNING - ***.exceptions.AirflowException: Task received SIGTERM signal
[2025-07-23T04:32:03.732+0000] {logging_mixin.py:154} WARNING - Call stack:
[2025-07-23T04:32:04.336+0000] {logging_mixin.py:154} WARNING -   File "/home/***/.local/bin/***", line 8, in <module>
    sys.exit(main())
[2025-07-23T04:32:04.353+0000] {logging_mixin.py:154} WARNING -   File "/home/***/.local/lib/python3.8/site-packages/***/__main__.py", line 57, in main
    args.func(args)
[2025-07-23T04:32:04.359+0000] {logging_mixin.py:154} WARNING -   File "/home/***/.local/lib/python3.8/site-packages/***/cli/cli_config.py", line 49, in command
    return func(*args, **kwargs)
[2025-07-23T04:32:04.367+0000] {logging_mixin.py:154} WARNING -   File "/home/***/.local/lib/python3.8/site-packages/***/utils/cli.py", line 114, in wrapper
    return f(*args, **kwargs)
[2025-07-23T04:32:04.375+0000] {logging_mixin.py:154} WARNING -   File "/home/***/.local/lib/python3.8/site-packages/***/utils/providers_configuration_loader.py", line 55, in wrapped_function
    return func(*args, **kwargs)
[2025-07-23T04:32:04.380+0000] {logging_mixin.py:154} WARNING -   File "/home/***/.local/lib/python3.8/site-packages/***/cli/commands/celery_command.py", line 242, in worker
    celery_app.worker_main(options)
[2025-07-23T04:32:04.407+0000] {logging_mixin.py:154} WARNING -   File "/home/***/.local/lib/python3.8/site-packages/celery/app/base.py", line 388, in worker_main
    self.start(argv=argv)
[2025-07-23T04:32:04.427+0000] {logging_mixin.py:154} WARNING -   File "/home/***/.local/lib/python3.8/site-packages/celery/app/base.py", line 368, in start
    celery.main(args=argv, standalone_mode=False)
[2025-07-23T04:32:04.433+0000] {logging_mixin.py:154} WARNING -   File "/home/***/.local/lib/python3.8/site-packages/click/core.py", line 1078, in main
    rv = self.invoke(ctx)
[2025-07-23T04:32:04.442+0000] {logging_mixin.py:154} WARNING -   File "/home/***/.local/lib/python3.8/site-packages/click/core.py", line 1688, in invoke
    return _process_result(sub_ctx.command.invoke(sub_ctx))
[2025-07-23T04:32:04.451+0000] {logging_mixin.py:154} WARNING -   File "/home/***/.local/lib/python3.8/site-packages/click/core.py", line 1434, in invoke
    return ctx.invoke(self.callback, **ctx.params)
[2025-07-23T04:32:04.452+0000] {logging_mixin.py:154} WARNING -   File "/home/***/.local/lib/python3.8/site-packages/click/core.py", line 783, in invoke
    return __callback(*args, **kwargs)
[2025-07-23T04:32:04.455+0000] {logging_mixin.py:154} WARNING -   File "/home/***/.local/lib/python3.8/site-packages/click/decorators.py", line 33, in new_func
    return f(get_current_context(), *args, **kwargs)
[2025-07-23T04:32:04.473+0000] {logging_mixin.py:154} WARNING -   File "/home/***/.local/lib/python3.8/site-packages/celery/bin/base.py", line 134, in caller
    return f(ctx, *args, **kwargs)
[2025-07-23T04:32:04.494+0000] {logging_mixin.py:154} WARNING -   File "/home/***/.local/lib/python3.8/site-packages/celery/bin/worker.py", line 356, in worker
    worker.start()
[2025-07-23T04:32:04.510+0000] {logging_mixin.py:154} WARNING -   File "/home/***/.local/lib/python3.8/site-packages/celery/worker/worker.py", line 202, in start
    self.blueprint.start(self)
[2025-07-23T04:32:04.537+0000] {logging_mixin.py:154} WARNING -   File "/home/***/.local/lib/python3.8/site-packages/celery/bootsteps.py", line 116, in start
    step.start(parent)
[2025-07-23T04:32:04.539+0000] {logging_mixin.py:154} WARNING -   File "/home/***/.local/lib/python3.8/site-packages/celery/bootsteps.py", line 365, in start
    return self.obj.start()
[2025-07-23T04:32:04.544+0000] {logging_mixin.py:154} WARNING -   File "/home/***/.local/lib/python3.8/site-packages/celery/concurrency/base.py", line 130, in start
    self.on_start()
[2025-07-23T04:32:04.550+0000] {logging_mixin.py:154} WARNING -   File "/home/***/.local/lib/python3.8/site-packages/celery/concurrency/prefork.py", line 109, in on_start
    P = self._pool = Pool(processes=self.limit,
[2025-07-23T04:32:04.561+0000] {logging_mixin.py:154} WARNING -   File "/home/***/.local/lib/python3.8/site-packages/celery/concurrency/asynpool.py", line 464, in __init__
    super().__init__(processes, *args, **kwargs)
[2025-07-23T04:32:04.564+0000] {logging_mixin.py:154} WARNING -   File "/home/***/.local/lib/python3.8/site-packages/billiard/pool.py", line 1045, in __init__
    self._create_worker_process(i)
[2025-07-23T04:32:04.568+0000] {logging_mixin.py:154} WARNING -   File "/home/***/.local/lib/python3.8/site-packages/celery/concurrency/asynpool.py", line 482, in _create_worker_process
    return super()._create_worker_process(i)
[2025-07-23T04:32:04.586+0000] {logging_mixin.py:154} WARNING -   File "/home/***/.local/lib/python3.8/site-packages/billiard/pool.py", line 1157, in _create_worker_process
    w.start()
[2025-07-23T04:32:04.598+0000] {logging_mixin.py:154} WARNING -   File "/home/***/.local/lib/python3.8/site-packages/billiard/process.py", line 120, in start
    self._popen = self._Popen(self)
[2025-07-23T04:32:04.601+0000] {logging_mixin.py:154} WARNING -   File "/home/***/.local/lib/python3.8/site-packages/billiard/context.py", line 331, in _Popen
    return Popen(process_obj)
[2025-07-23T04:32:04.606+0000] {logging_mixin.py:154} WARNING -   File "/home/***/.local/lib/python3.8/site-packages/billiard/popen_fork.py", line 22, in __init__
    self._launch(process_obj)
[2025-07-23T04:32:04.609+0000] {logging_mixin.py:154} WARNING -   File "/home/***/.local/lib/python3.8/site-packages/billiard/popen_fork.py", line 77, in _launch
    code = process_obj._bootstrap()
[2025-07-23T04:32:04.612+0000] {logging_mixin.py:154} WARNING -   File "/home/***/.local/lib/python3.8/site-packages/billiard/process.py", line 323, in _bootstrap
    self.run()
[2025-07-23T04:32:04.618+0000] {logging_mixin.py:154} WARNING -   File "/home/***/.local/lib/python3.8/site-packages/billiard/process.py", line 110, in run
    self._target(*self._args, **self._kwargs)
[2025-07-23T04:32:04.626+0000] {logging_mixin.py:154} WARNING -   File "/home/***/.local/lib/python3.8/site-packages/billiard/pool.py", line 291, in __call__
    sys.exit(self.workloop(pid=pid))
[2025-07-23T04:32:04.655+0000] {logging_mixin.py:154} WARNING -   File "/home/***/.local/lib/python3.8/site-packages/billiard/pool.py", line 361, in workloop
    result = (True, prepare_result(fun(*args, **kwargs)))
[2025-07-23T04:32:04.661+0000] {logging_mixin.py:154} WARNING -   File "/home/***/.local/lib/python3.8/site-packages/celery/app/trace.py", line 675, in fast_trace_task
    R, I, T, Rstr = tasks[task].__trace__(
[2025-07-23T04:32:04.668+0000] {logging_mixin.py:154} WARNING -   File "/home/***/.local/lib/python3.8/site-packages/celery/app/trace.py", line 477, in trace_task
    R = retval = fun(*args, **kwargs)
[2025-07-23T04:32:04.670+0000] {logging_mixin.py:154} WARNING -   File "/home/***/.local/lib/python3.8/site-packages/celery/app/trace.py", line 760, in __protected_call__
    return self.run(*args, **kwargs)
[2025-07-23T04:32:04.672+0000] {logging_mixin.py:154} WARNING -   File "/home/***/.local/lib/python3.8/site-packages/***/providers/celery/executors/celery_executor_utils.py", line 134, in execute_command
    _execute_in_fork(command_to_exec, celery_task_id)
[2025-07-23T04:32:04.673+0000] {logging_mixin.py:154} WARNING -   File "/home/***/.local/lib/python3.8/site-packages/***/providers/celery/executors/celery_executor_utils.py", line 168, in _execute_in_fork
    args.func(args)
[2025-07-23T04:32:04.676+0000] {logging_mixin.py:154} WARNING -   File "/home/***/.local/lib/python3.8/site-packages/***/cli/cli_config.py", line 49, in command
    return func(*args, **kwargs)
[2025-07-23T04:32:04.677+0000] {logging_mixin.py:154} WARNING -   File "/home/***/.local/lib/python3.8/site-packages/***/utils/cli.py", line 114, in wrapper
    return f(*args, **kwargs)
[2025-07-23T04:32:04.681+0000] {logging_mixin.py:154} WARNING -   File "/home/***/.local/lib/python3.8/site-packages/***/cli/commands/task_command.py", line 431, in task_run
    task_return_code = _run_task_by_selected_method(args, _dag, ti)
[2025-07-23T04:32:04.684+0000] {logging_mixin.py:154} WARNING -   File "/home/***/.local/lib/python3.8/site-packages/***/cli/commands/task_command.py", line 209, in _run_task_by_selected_method
    return _run_task_by_local_task_job(args, ti)
[2025-07-23T04:32:04.686+0000] {logging_mixin.py:154} WARNING -   File "/home/***/.local/lib/python3.8/site-packages/***/cli/commands/task_command.py", line 271, in _run_task_by_local_task_job
    ret = run_job(job=job_runner.job, execute_callable=job_runner._execute)
[2025-07-23T04:32:04.693+0000] {logging_mixin.py:154} WARNING -   File "/home/***/.local/lib/python3.8/site-packages/***/utils/session.py", line 79, in wrapper
    return func(*args, session=session, **kwargs)
[2025-07-23T04:32:04.694+0000] {logging_mixin.py:154} WARNING -   File "/home/***/.local/lib/python3.8/site-packages/***/jobs/job.py", line 289, in run_job
    return execute_job(job, execute_callable=execute_callable)
[2025-07-23T04:32:04.698+0000] {logging_mixin.py:154} WARNING -   File "/home/***/.local/lib/python3.8/site-packages/***/jobs/job.py", line 318, in execute_job
    ret = execute_callable()
[2025-07-23T04:32:04.700+0000] {logging_mixin.py:154} WARNING -   File "/home/***/.local/lib/python3.8/site-packages/***/jobs/local_task_job_runner.py", line 159, in _execute
    self.task_runner.start()
[2025-07-23T04:32:04.702+0000] {logging_mixin.py:154} WARNING -   File "/home/***/.local/lib/python3.8/site-packages/***/task/task_runner/standard_task_runner.py", line 45, in start
    self.process = self._start_by_fork()
[2025-07-23T04:32:04.707+0000] {logging_mixin.py:154} WARNING -   File "/home/***/.local/lib/python3.8/site-packages/***/task/task_runner/standard_task_runner.py", line 97, in _start_by_fork
    ret = args.func(args, dag=self.dag)
[2025-07-23T04:32:04.739+0000] {logging_mixin.py:154} WARNING -   File "/home/***/.local/lib/python3.8/site-packages/***/cli/cli_config.py", line 49, in command
    return func(*args, **kwargs)
[2025-07-23T04:32:04.741+0000] {logging_mixin.py:154} WARNING -   File "/home/***/.local/lib/python3.8/site-packages/***/utils/cli.py", line 114, in wrapper
    return f(*args, **kwargs)
[2025-07-23T04:32:04.744+0000] {logging_mixin.py:154} WARNING -   File "/home/***/.local/lib/python3.8/site-packages/***/cli/commands/task_command.py", line 431, in task_run
    task_return_code = _run_task_by_selected_method(args, _dag, ti)
[2025-07-23T04:32:04.750+0000] {logging_mixin.py:154} WARNING -   File "/home/***/.local/lib/python3.8/site-packages/***/cli/commands/task_command.py", line 211, in _run_task_by_selected_method
    return _run_raw_task(args, ti)
[2025-07-23T04:32:04.761+0000] {logging_mixin.py:154} WARNING -   File "/home/***/.local/lib/python3.8/site-packages/***/cli/commands/task_command.py", line 290, in _run_raw_task
    return ti._run_raw_task(
[2025-07-23T04:32:04.771+0000] {logging_mixin.py:154} WARNING -   File "/home/***/.local/lib/python3.8/site-packages/***/utils/session.py", line 79, in wrapper
    return func(*args, session=session, **kwargs)
[2025-07-23T04:32:04.776+0000] {logging_mixin.py:154} WARNING -   File "/home/***/.local/lib/python3.8/site-packages/***/models/taskinstance.py", line 1572, in _run_raw_task
    self.handle_failure(e, test_mode, context, session=session)
[2025-07-23T04:32:04.777+0000] {logging_mixin.py:154} WARNING -   File "/home/***/.local/lib/python3.8/site-packages/***/utils/session.py", line 76, in wrapper
    return func(*args, **kwargs)
[2025-07-23T04:32:04.778+0000] {logging_mixin.py:154} WARNING -   File "/home/***/.local/lib/python3.8/site-packages/***/models/taskinstance.py", line 1937, in handle_failure
    self.log.error("Task failed with exception", exc_info=(type(error), error, tb))
[2025-07-23T04:32:04.784+0000] {logging_mixin.py:154} WARNING -   File "/usr/local/lib/python3.8/logging/__init__.py", line 1475, in error
    self._log(ERROR, msg, args, **kwargs)
[2025-07-23T04:32:04.787+0000] {logging_mixin.py:154} WARNING -   File "/usr/local/lib/python3.8/logging/__init__.py", line 1589, in _log
    self.handle(record)
[2025-07-23T04:32:04.802+0000] {logging_mixin.py:154} WARNING -   File "/usr/local/lib/python3.8/logging/__init__.py", line 1599, in handle
    self.callHandlers(record)
[2025-07-23T04:32:04.806+0000] {logging_mixin.py:154} WARNING -   File "/usr/local/lib/python3.8/logging/__init__.py", line 1661, in callHandlers
    hdlr.handle(record)
[2025-07-23T04:32:04.808+0000] {logging_mixin.py:154} WARNING -   File "/usr/local/lib/python3.8/logging/__init__.py", line 954, in handle
    self.emit(record)
[2025-07-23T04:32:04.811+0000] {logging_mixin.py:154} WARNING -   File "/home/***/.local/lib/python3.8/site-packages/***/utils/log/file_task_handler.py", line 210, in emit
    self.handler.emit(record)
[2025-07-23T04:32:04.813+0000] {logging_mixin.py:154} WARNING - Message: 'Task failed with exception'
Arguments: ()
[2025-07-23T04:32:15.607+0000] {standard_task_runner.py:104} ERROR - Failed to execute job 191 for task trigger_streamlit_refresh ((psycopg2.OperationalError) could not translate host name "postgres" to address: Temporary failure in name resolution

(Background on this error at: https://sqlalche.me/e/14/e3q8); 4026)
[2025-07-23T04:32:16.666+0000] {process_utils.py:79} INFO - Process psutil.Process(pid=4026, status='terminated', exitcode=1, started='22:28:08') (4026) terminated with exit code 1
