[2025-07-23T07:55:45.190+0000] {taskinstance.py:1159} INFO - Dependencies all met for dep_context=non-requeueable deps ti=<TaskInstance: dashboard_loader_every_5_min.trigger_streamlit_refresh scheduled__2025-07-23T07:50:00+00:00 [queued]>
[2025-07-23T07:55:45.304+0000] {taskinstance.py:1159} INFO - Dependencies all met for dep_context=requeueable deps ti=<TaskInstance: dashboard_loader_every_5_min.trigger_streamlit_refresh scheduled__2025-07-23T07:50:00+00:00 [queued]>
[2025-07-23T07:55:45.315+0000] {taskinstance.py:1361} INFO - Starting attempt 1 of 1
[2025-07-23T07:55:45.624+0000] {taskinstance.py:1382} INFO - Executing <Task(PythonOperator): trigger_streamlit_refresh> on 2025-07-23 07:50:00+00:00
[2025-07-23T07:55:45.852+0000] {standard_task_runner.py:57} INFO - Started process 4470 to run task
[2025-07-23T07:55:46.113+0000] {standard_task_runner.py:84} INFO - Running: ['***', 'tasks', 'run', 'dashboard_loader_every_5_min', 'trigger_streamlit_refresh', 'scheduled__2025-07-23T07:50:00+00:00', '--job-id', '237', '--raw', '--subdir', 'DAGS_FOLDER/dashboard_loader_dag.py', '--cfg-path', '/tmp/tmp7649z931']
[2025-07-23T07:55:46.157+0000] {standard_task_runner.py:85} INFO - Job 237: Subtask trigger_streamlit_refresh
[2025-07-23T07:55:47.304+0000] {task_command.py:416} INFO - Running <TaskInstance: dashboard_loader_every_5_min.trigger_streamlit_refresh scheduled__2025-07-23T07:50:00+00:00 [running]> on host 539cb54e78a7
[2025-07-23T07:55:49.288+0000] {taskinstance.py:1662} INFO - Exporting env vars: AIRFLOW_CTX_DAG_OWNER='***' AIRFLOW_CTX_DAG_ID='dashboard_loader_every_5_min' AIRFLOW_CTX_TASK_ID='trigger_streamlit_refresh' AIRFLOW_CTX_EXECUTION_DATE='2025-07-23T07:50:00+00:00' AIRFLOW_CTX_TRY_NUMBER='1' AIRFLOW_CTX_DAG_RUN_ID='scheduled__2025-07-23T07:50:00+00:00'
[2025-07-23T07:55:50.763+0000] {logging_mixin.py:154} INFO - Dashboard refresh failed: HTTPConnectionPool(host='host.docker.internal', port=8501): Max retries exceeded with url: /refresh (Caused by NewConnectionError('<urllib3.connection.HTTPConnection object at 0x7d4ed01f48b0>: Failed to establish a new connection: [Errno 101] Network is unreachable'))
[2025-07-23T07:55:50.766+0000] {python.py:194} INFO - Done. Returned value was: None
[2025-07-23T07:55:50.954+0000] {taskinstance.py:1400} INFO - Marking task as SUCCESS. dag_id=dashboard_loader_every_5_min, task_id=trigger_streamlit_refresh, execution_date=20250723T075000, start_date=20250723T075545, end_date=20250723T075550
[2025-07-23T07:55:51.465+0000] {local_task_job_runner.py:228} INFO - Task exited with return code 0
[2025-07-23T07:55:51.841+0000] {taskinstance.py:2778} INFO - 0 downstream tasks scheduled from follow-on schedule check
